<?xml version="1.0" ?>
<robot name="mobilerobot">
  <material name="black">
    <color rgba="0.2 0.2 0.2 1"/>
  </material>
  <material name="grey">
    <color rgba="0.75 0.75 0.75 1"/>
  </material>
  <link name="base_link">
    <visual>
      <geometry>
        <mesh filename="package://mobile_robot_description/meshes/raspi_mouse_body.stl"/>
      </geometry>
      <material name="grey"/>
      <origin xyz="-0.041 -0.05 -0.02575" rpy="0 0 0"/>
    </visual>
    <visual name="regulators">
      <geometry>
        <box size="0.005 0.065 0.02"/>
      </geometry>
      <origin xyz="0.04 0 0.036" rpy="0 0 0"/>
      <material name="black"/>
    </visual>
    <visual name="connector">
      <geometry>
        <box size="0.075 0.016 0.026"/>
      </geometry>
      <origin xyz="0 -0.027 0.039" rpy="0 0 0"/>
      <material name="black"/>
    </visual>
    <collision>
      <geometry>
        <box size="0.13 0.1 0.078"/>
      </geometry>
      <origin xyz="0 0 0.013" rpy="0 0 0"/>
    </collision>
  </link>

  <link name="caster_support">
    <visual>
      <geometry>
        <mesh filename="package://mobile_robot_description/meshes/mobile_robot_caster.stl"/>
      </geometry>
      <origin xyz="0 0 0" rpy="0 0 0"/>
      <material name="grey"/>
    </visual>
    <collision>
      <geometry>
        <box size="0.04 0.009 0.025"/>
      </geometry>
      <origin xyz="-0.015 0 0" rpy="0 0 0"/>
    </collision>
  </link>

  <joint name="caster_support_joint" type="continuous">
    <axis xyz="0 0 1"/>
    <parent link="base_link"/>
    <child link="caster_support"/>
    <origin xyz="-0.065 0 -0.01" rpy="0 0 0"/>
  </joint>

  <link name="caster_wheel">
    <visual>
      <geometry>
        <cylinder length="0.005" radius="0.02"/>
      </geometry>
      <material name="black"/>
    </visual>
    <collision>
      <geometry>
        <cylinder length="0.005" radius="0.02"/>
      </geometry>
    </collision>
  </link>

  <joint name="caster_wheel_joint" type="continuous">
    <axis xyz="0 0 1"/>
    <parent link="caster_support"/>
    <child link="caster_wheel"/>
    <origin xyz="-0.02 0 -0.02" rpy="-1.5708 0 0"/>
  </joint>

  <link name="right_wheel">
    <visual>
      <geometry>
        <cylinder length="0.008" radius="0.024"/>
      </geometry>
      <material name="black"/>
    </visual>
    <collision>
      <geometry>
        <cylinder length="0.008" radius="0.024"/>
      </geometry>
    </collision>
  </link>

  <joint name="right_wheel_joint" type="continuous">
    <axis xyz="0 0 1"/>
    <parent link="base_link"/>
    <child link="right_wheel"/>
    <origin xyz="0 0.054 -0.021" rpy="-1.5708 0 0"/>
  </joint>

  <link name="left_wheel">
    <visual>
      <geometry>
        <cylinder length="0.008" radius="0.024"/>
      </geometry>
      <material name="black"/>
    </visual>
    <collision>
      <geometry>
        <cylinder length="0.008" radius="0.024"/>
      </geometry>
    </collision>
  </link>

  <joint name="left_wheel_joint" type="continuous">
    <axis xyz="0 0 1"/>
    <parent link="base_link"/>
    <child link="left_wheel"/>
    <origin xyz="0 -0.054 -0.021" rpy="-1.5708 0 0"/>
  </joint>

  <link name="laser">
    <visual>
      <geometry>
        <box size="0.05 0.05 0.05"/>
      </geometry>
      <material name="red">
        <color rgba="0.9 0.1 0.1 1"/>
      </material>
    </visual>
    <collision>
      <geometry>
        <box size="0.05 0.05 0.05"/>
      </geometry>
    </collision>
  </link>

  <joint name="laser_joint" type="fixed">
    <parent link="base_link"/>
    <child link="laser"/>
    <origin xyz="0 0 0.051" rpy="0 0 0"/>
  </joint>
</robot>
